Workbook

Sheet GW Spend + DMR
A1: Year | B1: Projected Grantmaking - linear | C1: Projected Grantmaking - flat | D1: Projected Grantmaking - average | G1: Notes
A2: 2024 | B2: =3.97*10^8 -> 397000000 | C2: =B2 -> 397000000 | D2: =AVERAGE(B2:C2) -> 397000000 | G2: GiveWell’s 2024 Metrics and Impact
A3: 2025 | B3: =4.18*10^8 -> 418000000 | C3: =B3 -> 418000000 | D3: =AVERAGE(B3:C3) -> 418000000 | G3: From GW in email from Hannah Bell 2/19/26
A4: 2026 | B4: =5*10^8 -> 500000000 | C4: =B4 -> 500000000 | D4: =AVERAGE(B4:C4) -> 500000000 | G4: Source: Estimate from GW (Hannah Bell via email to Carmen, 2/19
A5: 2027 | B5: =(($B$4-$B$2)/($A$4-$A$2))*(A5-$A$4) + $B$4 -> 551500000 | C5: =C4 -> 500000000 | D5: =AVERAGE(B5:C5) -> 525750000 | G5: In one scenario, assume that GW's portfolio grows linearly per year, and in the other assume it's constant. We take the average to get an overall estimate of what their portfolio will be in the next 3 years
A6: 2028 | B6: =(($B$4-$B$2)/($A$4-$A$2))*(A6-$A$4) + $B$4 -> 603000000 | C6: =C5 -> 500000000 | D6: =AVERAGE(B6:C6) -> 551500000
A7: Total (2026-2028) | B7: =SUM(B4:B6) -> 1654500000 | C7: =SUM(C4:C6) -> 1500000000 | D7: =SUM(D4:D6) -> 1577250000
A9: Diminishing Returns
A10: Power | B10: =ln(0.9)/ln(1/2) -> 0.15200309 | C10: Assume 10% decline in cost-effectiveness per doubling of funds | G10: Just an assumption, but GiveWell has even raised its bar over time and GW has been a small portion of all GHD giving, so I assume there are many more cost-effective opportunities near GW's current bar for billions of dollars in the future
A12: Results, transposed:
A13: Additional funding | B13: {=TRANSPOSE(A19:A109)} -> 10000000 | C13: 20000000 | D13: 30000000 | E13: 40000000 | F13: 50000000 | G13: 60000000 | H13: 70000000 | I13: 80000000 | J13: 90000000 | K13: 100000000 | L13: 110000000 | M13: 120000000 | N13: 130000000 | O13: 140000000 | P13: 150000000 | Q13: 160000000 | R13: 170000000 | S13: 180000000 | T13: 190000000 | U13: 200000000 | V13: 210000000 | W13: 220000000 | X13: 230000000 | Y13: 240000000 | Z13: 250000000 | AA13: 260000000 | AB13: 270000000 | AC13: 280000000 | AD13: 290000000 | AE13: 300000000 | AF13: 310000000 | AG13: 320000000 | AH13: 330000000 | AI13: 340000000 | AJ13: 350000000 | AK13: 360000000 | AL13: 370000000 | AM13: 380000000 | AN13: 390000000 | AO13: 400000000 | AP13: 410000000 | AQ13: 420000000 | AR13: 430000000 | AS13: 440000000 | AT13: 450000000 | AU13: 460000000 | AV13: 470000000 | AW13: 480000000 | AX13: 490000000 | AY13: 500000000 | AZ13: 510000000 | BA13: 520000000 | BB13: 530000000 | BC13: 540000000 | BD13: 550000000 | BE13: 560000000 | BF13: 570000000 | BG13: 580000000 | BH13: 590000000 | BI13: 600000000 | BJ13: 610000000 | BK13: 620000000 | BL13: 630000000 | BM13: 640000000 | BN13: 650000000 | BO13: 660000000 | BP13: 670000000 | BQ13: 680000000 | BR13: 690000000 | BS13: 700000000 | BT13: 710000000 | BU13: 720000000 | BV13: 730000000 | BW13: 740000000 | BX13: 750000000 | BY13: 760000000 | BZ13: 770000000 | CA13: 780000000 | CB13: 790000000 | CC13: 800000000 | CD13: 810000000 | CE13: 820000000 | CF13: 830000000 | CG13: 840000000 | CH13: 850000000 | CI13: 860000000 | CJ13: 870000000 | CK13: 880000000 | CL13: 890000000 | CM13: 900000000
A14: funding up to | B14: 10 | C14: 20 | D14: 30 | E14: 40 | F14: 50 | G14: 60 | H14: 70 | I14: 80 | J14: 90 | K14: 100 | L14: 110 | M14: 120 | N14: 130 | O14: 140 | P14: 150 | Q14: 160 | R14: 170 | S14: 180 | T14: 190 | U14: 200 | V14: 210 | W14: 220 | X14: 230 | Y14: 240 | Z14: 250 | AA14: 260 | AB14: 270 | AC14: 280 | AD14: 290 | AE14: 300 | AF14: 310 | AG14: 320 | AH14: 330 | AI14: 340 | AJ14: 350 | AK14: 360 | AL14: 370 | AM14: 380 | AN14: 390 | AO14: 400 | AP14: 410 | AQ14: 420 | AR14: 430 | AS14: 440 | AT14: 450 | AU14: 460 | AV14: 470 | AW14: 480 | AX14: 490 | AY14: 500 | AZ14: 510 | BA14: 520 | BB14: 530 | BC14: 540 | BD14: 550 | BE14: 560 | BF14: 570 | BG14: 580 | BH14: 590 | BI14: 600 | BJ14: 610 | BK14: 620 | BL14: 630 | BM14: 640 | BN14: 650 | BO14: 660 | BP14: 670 | BQ14: 680 | BR14: 690 | BS14: 700 | BT14: 710 | BU14: 720 | BV14: 730 | BW14: 740 | BX14: 750 | BY14: 760 | BZ14: 770 | CA14: 780 | CB14: 790 | CC14: 800 | CD14: 810 | CE14: 820 | CF14: 830 | CG14: 840 | CH14: 850 | CI14: 860 | CJ14: 870 | CK14: 880 | CL14: 890 | CM14: 900
A15: Marginal Cost-Effectiveness Relative to Baseline | B15: {=TRANSPOSE(B19:B109)} -> 1 | C15: 0.99903978 | D15: 0.99808651 | E15: 0.99714008 | F15: 0.99620042 | G15: 0.99526742 | H15: 0.99434101 | I15: 0.99342109 | J15: 0.99250759 | K15: 0.99160041 | L15: 0.99069948 | M15: 0.98980471 | N15: 0.98891603 | O15: 0.98803337 | P15: 0.98715664 | Q15: 0.98628577 | R15: 0.9854207 | S15: 0.98456134 | T15: 0.98370762 | U15: 0.98285949 | V15: 0.98201686 | W15: 0.98117968 | X15: 0.98034788 | Y15: 0.9795214 | Z15: 0.97870016 | AA15: 0.97788412 | AB15: 0.9770732 | AC15: 0.97626735 | AD15: 0.97546652 | AE15: 0.97467063 | AF15: 0.97387964 | AG15: 0.97309349 | AH15: 0.97231212 | AI15: 0.97153548 | AJ15: 0.97076352 | AK15: 0.96999619 | AL15: 0.96923343 | AM15: 0.96847519 | AN15: 0.96772142 | AO15: 0.96697208 | AP15: 0.96622711 | AQ15: 0.96548647 | AR15: 0.96475011 | AS15: 0.96401798 | AT15: 0.96329005 | AU15: 0.96256626 | AV15: 0.96184657 | AW15: 0.96113094 | AX15: 0.96041932 | AY15: 0.95971168 | AZ15: 0.95900798 | BA15: 0.95830816 | BB15: 0.95761219 | BC15: 0.95692004 | BD15: 0.95623166 | BE15: 0.95554702 | BF15: 0.95486608 | BG15: 0.95418879 | BH15: 0.95351513 | BI15: 0.95284506 | BJ15: 0.95217853 | BK15: 0.95151553 | BL15: 0.95085601 | BM15: 0.95019994 | BN15: 0.94954728 | BO15: 0.94889801 | BP15: 0.94825208 | BQ15: 0.94760948 | BR15: 0.94697015 | BS15: 0.94633409 | BT15: 0.94570124 | BU15: 0.94507159 | BV15: 0.94444511 | BW15: 0.94382175 | BX15: 0.94320151 | BY15: 0.94258433 | BZ15: 0.94197021 | CA15: 0.9413591 | CB15: 0.94075099 | CC15: 0.94014584 | CD15: 0.93954363 | CE15: 0.93894433 | CF15: 0.93834791 | CG15: 0.93775436 | CH15: 0.93716364 | CI15: 0.93657572 | CJ15: 0.93599059 | CK15: 0.93540822 | CL15: 0.93482859 | CM15: 0.93425166
A17: Calculations:
A18: Amount of Additional Funding | B18: Marginal Cost-Effectiveness Relative to Baseline
A19: 10000000 | B19: =(1+(A19-10*10^6)/$D$7)^(-$B$10) -> 1
A20: =A19+10*10^6 -> 20000000 | B20: =(1+(A20-10*10^6)/$D$7)^(-$B$10) -> 0.99903978
A21: =A20+10*10^6 -> 30000000 | B21: =(1+(A21-10*10^6)/$D$7)^(-$B$10) -> 0.99808651
A22: =A21+10*10^6 -> 40000000 | B22: =(1+(A22-10*10^6)/$D$7)^(-$B$10) -> 0.99714008
A23: =A22+10*10^6 -> 50000000 | B23: =(1+(A23-10*10^6)/$D$7)^(-$B$10) -> 0.99620042
A24: =A23+10*10^6 -> 60000000 | B24: =(1+(A24-10*10^6)/$D$7)^(-$B$10) -> 0.99526742
A25: =A24+10*10^6 -> 70000000 | B25: =(1+(A25-10*10^6)/$D$7)^(-$B$10) -> 0.99434101
A26: =A25+10*10^6 -> 80000000 | B26: =(1+(A26-10*10^6)/$D$7)^(-$B$10) -> 0.99342109
A27: =A26+10*10^6 -> 90000000 | B27: =(1+(A27-10*10^6)/$D$7)^(-$B$10) -> 0.99250759
A28: =A27+10*10^6 -> 100000000 | B28: =(1+(A28-10*10^6)/$D$7)^(-$B$10) -> 0.99160041
A29: =A28+10*10^6 -> 110000000 | B29: =(1+(A29-10*10^6)/$D$7)^(-$B$10) -> 0.99069948
A30: =A29+10*10^6 -> 120000000 | B30: =(1+(A30-10*10^6)/$D$7)^(-$B$10) -> 0.98980471
A31: =A30+10*10^6 -> 130000000 | B31: =(1+(A31-10*10^6)/$D$7)^(-$B$10) -> 0.98891603
... A108: =A107+10*10^6 -> 900000000 | B108: =(1+(A108-10*10^6)/$D$7)^(-$B$10) -> 0.93425166

Sheet Percentiles_for_python
A1: Summary of Preliminary Estimates for GW Effects
A2: Final distributions
A3: Life years saved/$1M | B3: 5th-percentile | C3: Mean | D3: 95th percentile | F3: Assume that saving a life leads to 60 more years of life lived
A4: 0-5 years | B4: ='Overall Grantmaking'!B4*60 -> 10066.961 | C4: ='Overall Grantmaking'!C4*60 -> 13739.685 | D4: ='Overall Grantmaking'!D4*60 -> 18152.237
A5: 5-10 years | B5: ='Overall Grantmaking'!B5*60 -> 782.98589 | C5: ='Overall Grantmaking'!C5*60 -> 1068.6422 | D5: ='Overall Grantmaking'!D5*60 -> 1411.8407
A6: 10-20 years | B6: ='Overall Grantmaking'!B6*60 -> 279.63782 | C6: ='Overall Grantmaking'!C6*60 -> 381.65791 | D6: ='Overall Grantmaking'!D6*60 -> 504.22882
A7: 20-100 years | B7: ='Overall Grantmaking'!B7*60 -> 55.927563 | C7: ='Overall Grantmaking'!C7*60 -> 76.331583 | D7: ='Overall Grantmaking'!D7*60 -> 100.84576
A8: 100-500 years | B8: ='Overall Grantmaking'!B8*60 -> 0 | C8: ='Overall Grantmaking'!C8*60 -> 0 | D8: ='Overall Grantmaking'!D8*60 -> 0
A9: 500+ years | B9: ='Overall Grantmaking'!B9*60 -> 0 | C9: ='Overall Grantmaking'!C9*60 -> 0 | D9: ='Overall Grantmaking'!D9*60 -> 0
A11: YLDs averted/$1M | B11: 5th-percentile | C11: Mean | D11: 95th percentile
A12: 0-5 years | B12: ='Overall Grantmaking'!B12 -> 2243.2959 | C12: ='Overall Grantmaking'!C12 -> 3061.7162 | D12: ='Overall Grantmaking'!D12 -> 4044.9981
A13: 5-10 years | B13: ='Overall Grantmaking'!B13 -> 174.47857 | C13: ='Overall Grantmaking'!C13 -> 238.13348 | D13: ='Overall Grantmaking'!D13 -> 314.61097
A14: 10-20 years | B14: ='Overall Grantmaking'!B14 -> 62.313775 | C14: ='Overall Grantmaking'!C14 -> 85.047672 | D14: ='Overall Grantmaking'!D14 -> 112.36106
A15: 20-100 years | B15: ='Overall Grantmaking'!B15 -> 12.462755 | C15: ='Overall Grantmaking'!C15 -> 17.009534 | D15: ='Overall Grantmaking'!D15 -> 22.472212
A16: 100-500 years | B16: ='Overall Grantmaking'!B16 -> 0 | C16: ='Overall Grantmaking'!C16 -> 0 | D16: ='Overall Grantmaking'!D16 -> 0
A17: 500+ years | B17: ='Overall Grantmaking'!B17 -> 0 | C17: ='Overall Grantmaking'!C17 -> 0 | D17: ='Overall Grantmaking'!D17 -> 0
A19: Income Doublings/$1M | B19: 5th-percentile | C19: Mean | D19: 95th percentile
A20: 0-5 years | B20: ='Overall Grantmaking'!B20 -> 1946.5533 | C20: ='Overall Grantmaking'!C20 -> 2656.7132 | D20: ='Overall Grantmaking'!D20 -> 3509.9268
A21: 5-10 years | B21: ='Overall Grantmaking'!B21 -> 151.39859 | C21: ='Overall Grantmaking'!C21 -> 206.63325 | D21: ='Overall Grantmaking'!D21 -> 272.99431
A22: 10-20 years | B22: ='Overall Grantmaking'!B22 -> 1351.7731 | C22: ='Overall Grantmaking'!C22 -> 1844.9397 | D22: ='Overall Grantmaking'!D22 -> 2437.4492
A23: 20-100 years | B23: ='Overall Grantmaking'!B23 -> 7364.46 | C23: ='Overall Grantmaking'!C23 -> 10051.231 | D23: ='Overall Grantmaking'!D23 -> 13279.223
A24: 100-500 years | B24: ='Overall Grantmaking'!B24 -> 0 | C24: ='Overall Grantmaking'!C24 -> 0 | D24: ='Overall Grantmaking'!D24 -> 0
A25: 500+ years | B25: ='Overall Grantmaking'!B25 -> 0 | C25: ='Overall Grantmaking'!C25 -> 0 | D25: ='Overall Grantmaking'!D25 -> 0

Sheet Overall Grantmaking
A1: Summary of Preliminary Estimates for GW Effects | I1: Notes
A2: Final distributions | I2: Legend
A3: Lives saved/$1M | B3: 5th-percentile | C3: Mean | D3: 95th percentile | I3: Data/Input
A4: 0-5 years | B4: =B$57*$B62 -> 167.78269 | C4: =C$57*$B62 -> 228.99475 | D4: =D$57*$B62 -> 302.53729 | I4: Informed Estimate
A5: 5-10 years | B5: =B$57*$B63 -> 13.049765 | C5: =C$57*$B63 -> 17.810703 | D5: =D$57*$B63 -> 23.530678 | I5: Calculation
A6: 10-20 years | B6: =B$57*$B64 -> 4.6606303 | C6: =C$57*$B64 -> 6.3609652 | D6: =D$57*$B64 -> 8.4038137
A7: 20-100 years | B7: =B$57*$B65 -> 0.93212606 | C7: =C$57*$B65 -> 1.272193 | D7: =D$57*$B65 -> 1.6807627
A8: 100-500 years | B8: =B$57*$B66 -> 0 | C8: =C$57*$B66 -> 0 | D8: =D$57*$B66 -> 0
A9: 500+ years | B9: =B$57*$B67 -> 0 | C9: =C$57*$B67 -> 0 | D9: =D$57*$B67 -> 0
A11: YLDs averted/$1M | B11: 5th-percentile | C11: Mean | D11: 95th percentile
A12: 0-5 years | B12: =B$58*$C62 -> 2243.2959 | C12: =C$58*$C62 -> 3061.7162 | D12: =D$58*$C62 -> 4044.9981
A13: 5-10 years | B13: =B$58*$C63 -> 174.47857 | C13: =C$58*$C63 -> 238.13348 | D13: =D$58*$C63 -> 314.61097
A14: 10-20 years | B14: =B$58*$C64 -> 62.313775 | C14: =C$58*$C64 -> 85.047672 | D14: =D$58*$C64 -> 112.36106
A15: 20-100 years | B15: =B$58*$C65 -> 12.462755 | C15: =C$58*$C65 -> 17.009534 | D15: =D$58*$C65 -> 22.472212
A16: 100-500 years | B16: =B$58*$C66 -> 0 | C16: =C$58*$C66 -> 0 | D16: =D$58*$C66 -> 0
A17: 500+ years | B17: =B$58*$C67 -> 0 | C17: =C$58*$C67 -> 0 | D17: =D$58*$C67 -> 0
A19: Income Doublings/$1M | B19: 5th-percentile | C19: Mean | D19: 95th percentile
A20: 0-5 years | B20: =B$59*$D62 -> 1946.5533 | C20: =C$59*$D62 -> 2656.7132 | D20: =D$59*$D62 -> 3509.9268
A21: 5-10 years | B21: =B$59*$D63 -> 151.39859 | C21: =C$59*$D63 -> 206.63325 | D21: =D$59*$D63 -> 272.99431
A22: 10-20 years | B22: =B$59*$D64 -> 1351.7731 | C22: =C$59*$D64 -> 1844.9397 | D22: =D$59*$D64 -> 2437.4492
A23: 20-100 years | B23: =B$59*$D65 -> 7364.46 | C23: =C$59*$D65 -> 10051.231 | D23: =D$59*$D65 -> 13279.223
A24: 100-500 years | B24: =B$59*$D66 -> 0 | C24: =C$59*$D66 -> 0 | D24: =D$59*$D66 -> 0
A25: 500+ years | B25: =B$59*$D67 -> 0 | C25: =C$59*$D67 -> 0 | D25: =D$59*$D67 -> 0
A27: Computations
A28: GW units value per $1M per 1x benchmark | B28: ='Cash Transfers Value'!B5 -> 3280.3273 | I28: See cash transfers sheet
A30: Value Type | B30: Percent benefits | C30: GW Moral Weight | I30: We'll assume for this preliminary version that an intervention's distribution of value across effect type is independent from the intervention's cost-effectiveness.
A31: Mortality Effects | B31: ='Percent Distribution Across Int'!D11 -> 0.56569416 | C31: =IFERROR(__xludf.DUMMYFUNCTION("AVERAGE.Weighted('Percent Distribution Across Int'!G3:G9, 'Percent Distribution Across Int'!B3:B9)"),115.61176470588235) -> 115.61176
A32: Morbidity Effects | B32: ='Percent Distribution Across Int'!C11 -> 0.15046896 | C32: 2.3
A33: Income Effects | B33: ='Percent Distribution Across Int'!E11 -> 0.28383688 | C33: 1
C35: Distribution of cost-effectiveness (x benchmark)
A36: Grantmaking Value (multiples benchmark) | B36: Percent Grantmaking in 2025 | C36: 5th percentile (x benchmark) | D36: Best guess (x benchmark) | E36: 95th percentile (x benchmark) | I36: We'll estimate the distribution of cost-effectiveness for GW's grantmaking using data on their 2025 grantmaking and their own estimates of the share of grant dollars that were <8x cost-effective as the benchmark, 8-16x, and >16x
A37: <8x | B37: 0.05 | C37: 2 | D37: 6 | E37: 8 | I37: We'll assume that the worst-case scenario for a grant that is <8x the benchmark is that it is 2x the benchmark, or half as cost-effective than GiveDirectly (3.3x) . We'll assume a symmetric distribution, making the average cost-effectiveness of a grant in this category 6x benchmark. This is just an assumption, but it appears that some things GW has funded are as low as 2x (see https://share.transistor.fm/s/e84ac0cc/transcript) There's a 5% chance that a grant GW thinks is <8x is actually >8x.
A38: 8-16x | B38: 0.68 | C38: 8 | D38: 12 | E38: 16 | I38: Assume a symmetric distribution with 5th percentile of 8x and 95th percentile 16x. This implies a 10% chance that grants categorized as 8-16x are miscategorized.
A39: >16x | B39: 0.27 | C39: 16 | D39: 28 | E39: 44 | I39: Assume that a typical grantmaking opportunity that exceeds 16x the benchmark is like one given to New Incentives. New Incentives' programs' cost-effectiveness could be as high as 44x. With a lognormal distribution that has a 90% confidence interval between 16 and 44, we would get an average cost-effectiveness of 28.
C41: Distribution of cost effectiveness (units value/$1M)
A42: Grantmaking Value (multiples benchmark) | B42: =B36 -> Percent Grantmaking in 2025 | C42: 5th percentile (units/$1M) | D42: Best Guess (units/$1M) | E42: 95th percentile (units/$1M) | I42: Multiply by the number of units of value per x the benchmark per $1M, to get units of value per $1M
A43: <8x | B43: =B37 -> 0.05 | C43: =C37*$B$28 -> 6560.6545 | D43: =D37*$B$28 -> 19681.964 | E43: =E37*$B$28 -> 26242.618
A44: 8-16x | B44: =B38 -> 0.68 | C44: =C38*$B$28 -> 26242.618 | D44: =D38*$B$28 -> 39363.927 | E44: =E38*$B$28 -> 52485.236
A45: >16x | B45: =B39 -> 0.27 | C45: =C39*$B$28 -> 52485.236 | D45: =D39*$B$28 -> 91849.164 | E45: =E39*$B$28 -> 144334.4
A48: Weighted Average cost effectiveness | B48: 5th percentile (units/$1M) | C48: Best guess (units/$1M) | D48: 95th percentile (units/$1M)
...

Sheet Percent Distribution Across Int
A1: Distribution of 2025 Funding Across Interventions | C1: Distribution of Value Across Benefit Types Under GW's Moral Weights | I1: Notes
B2: Percent funding in 2025 | C2: Morbidity effects (% value) | D2: Lives saved effects (% value) | E2: Income effects (% value) | F2: Total | G2: Moral weight for lives saved | I2: Source | J2: Morbidity effects | K2: Lives saved effects | L2: Income effects
A3: Malaria Prevention and Treatment | B3: 0.38 | C3: =0.09+0.09*0.58 -> 0.1422 | D3: =(1-C3)*(0.59+0.09) -> 0.583304 | E3: =(1-C3)*(0.32) -> 0.274496 | F3: =SUM(C3:E3) -> 1 | G3: 116 | I3: Assume that AMF is roughly representative here of the typical malaria prevention grant in terms of its distribution of effects across value types. | J3: Malaria morbidity contributes 9% of the effects, and short-term anemia effects (which we assume to be 58% quality-of-life effects, see row on Iron fortification) account for another 9% of benefits. See here | K3: In Uganda, GW estimates that 59% of benefits come from reduced mortality among children under 5, and 9% of the benefits come from reduced mortality over 5. This is renormalized to account for the morbidity effects. Estimates of the % can vary by country, but we assume that Uganda is roughly representative | L3: GW estimates that 32% of the benefits of reducing malaria come later in life from income increases. We renormalize this to account for morbidity effects.
A4: Vaccinations | B4: 0.12 | C4: =0.06+0.007 -> 0.067 | D4: =(1-C4)*(0.66+0.1) -> 0.70908 | E4: =(1-C4)*(0.22+0.02) -> 0.22392 | F4: =SUM(C4:E4) -> 1 | G4: 116 | J4: Sum "Morbidity effects from directly incentivized vaccines and rotavirus" and "Morbidity effects of indirectly incentivized vaccines besides rotavirus (i.e., polio, yellow fever, rubella, mumps, varicella meningitis A)" in linked spreadsheet | K4: 66% of the value came from lives saved under 5, 10% from lives saved over 5, before renormalizing for the fact that some of this value is actually due to morbidity reductions. | L4: 22% of the value comes from long-term consumption increases for children getting vaccines now, before renormalizing for morbidity effects , and 2% comes now.
A5: Malnutrition Treatment | B5: 0.09 | C5: =0.059-0.02 -> 0.039 | D5: =(1-C5)*(44059/52937) -> 0.79983186 | E5: =(1-C5)*(8878/52937) -> 0.16116814 | F5: =SUM(C5:E5) -> 1 | G5: 118 | J5: For Taimaka, GW estimates that 3.9% of the value comes from averting morbidity from malnutrition (5.9%-2.0%). See link. | K5: GW estimates that, for a grant they make to Taimaka, 52937 units of value are created, of which 44059 come from mortality reductions. We normalize this for the fact that some will come from morbidity effects. See here | L5: Of the 52937 units of value from a grant to Taimaka, 8878 come from long-term income increases. See here
A6: Water | B6: 0.09 | C6: =128/(2119+966+128+1426) -> 0.027592153 | D6: =(2119+966)/(2119+966+128+1426) -> 0.66501401 | E6: =1426/(2119+966+128+1426) -> 0.30739383 | F6: =SUM(C6:E6) -> 1 | G6: 108 | I6: Assume that GiveWell's water quality portfolio's effects have a similar distribution across benefit streams as ILC interventions in Kenya. | J6: GW estimates that, per 100k people covered by ILC, 128 units of value are created from reduced morbidity, in Kenya/ | K6: GW estimates that, per 100k people covered, 2119 and 966 units of value are created from saving lives of people under-5 and over-5, respectively, in Kenya. | L6: GW estimates that, per 100k people covered by ILC in Kenya, 1426 units of value are created.
A7: VAS | B7: 0.07 | C7: =0.06+0.09*0.58+0.09*0.58 -> 0.1644 | D7: =(1-C7)*0.8 -> 0.66848 | E7: =(1-C7)*0.2 -> 0.16712 | F7: =SUM(C7:E7) -> 1 | G7: 119 | J7: GW estimates that 6% of the value comes from reduced infectious disease morbidity, 9% due to reduced anemia effects in the short term (58% of which is from reduced morbidity), and 9% to reductions in blindness (58% of which I assume comes from reduced morbidity and maybe 42% comes from income) | K7: GW estimates that 80% of the benefits of VAS come from reduced child mortality. We normalize for the fact that some is due to morbidity reductions. | L7: GW estimates that 20% of the value comes from long-term income increases. We normalize for morbidity effects.
A8: Iron Fortification | B8: 0.07 | C8: 0.58 | D8: 0 | E8: =0.34+0.08 -> 0.42 | F8: =SUM(C8:E8) -> 1 | G8: 116 | J8: GW estimates 58% of the value of iron fortification comes from reduced morbidity of anemia | K8: GW does not model any life-saving effects from iron fortification and supplementation | L8: 34% of the value is from cognitive benefits in adults and 8% from cognitive benefits in kids.
A9: Livelihoods | B9: 0.03 | C9: ='Cash Transfers Value'!F36 -> 0.090909091 | D9: ='Cash Transfers Value'!F35 -> 0.093054743 | E9: ='Cash Transfers Value'!F34 -> 0.81603617 | F9: =SUM(C9:E9) -> 1 | G9: 116 | I9: Assume the distribution of benefits is similar to that of cash transfers through GiveDirectly | J9: See Cash Transfers Value tab
A10: Family Planning | B10: 0.02 | C10: =(0.0439+0.0063+0.23)/0.7002 -> 0.40017138 | D10: =(0.0387+0.0103+0.0906)/0.7002 -> 0.19937161 | E10: =(0.0511+0.1913+0.038)/0.7002 -> 0.40045701 | F10: =SUM(C10:E10) -> 1 | J10: GW estimates that each year of contraception produces 0.7 units of value, 0.04 of which come from reduced maternal morbidity, 0.006 from reduced child morbidity, and 0.23 from improved mental health for women. | K10: Of the 0.7 units of value GW estimates are created by each year of contraception, they estimate that 0.05 comes from reduced maternal mortality and 0.09 from reduced child mortality. | L10: Of the 0.7 units of value created by each year of modern contraception, GW estimates that 0.05 comes from greater earnings for women, 0.04 from reduced medical expenses, and 0.19 comes from greater resources (consumption) for existing children.
A11: Total | B11: =SUM(B3:B10) -> 0.87 | C11: =IFERROR(__xludf.DUMMYFUNCTION("AVERAGE.WEIGHTED(C3:C10, $B3:$B10)"),0.15046895877323116) -> 0.15046896 | D11: =IFERROR(__xludf.DUMMYFUNCTION("AVERAGE.WEIGHTED(D3:D10, $B3:$B10)"),0.5656941639123617) -> 0.56569416 | E11: =IFERROR(__xludf.DUMMYFUNCTION("AVERAGE.WEIGHTED(E3:E10, $B3:$B10)"),0.2838368773144071) -> 0.28383688 | F11: =SUM(C11:E11) -> 1
A12: Other Research, Scoping, and Planning Grants | B12: 0.04 | I12: Not assessed because too vague
A13: Other Health Programs | B13: 0.08 | I13: Not assessed because too vague

Sheet Cash Transfers Value
H1: Notes
A2: Cash Transfers (Using GiveDirectly CEA) | B2: Total | H2: The purpose of this sheet is to estimate the total number of units of value per 1x cash unit used in GiveWell's cost-effectiveness estimates. We also estimate the distribution of the value of cash transfers that comes from each benefit (YLDs averted, lives saved, income doublings) using GW's moral weights.
A3: Units value per $1M goes to GiveDirectly | B3: =SUMPRODUCT(B15:F15, B9:F9) -> 10825.08
A4: GiveDirectly multiples of benchmark | B4: 3.3 | H4: As of 2024, GW says that GiveDirectly is now 3.3x their benchmark value.
A5: GW units value per multiple of benchmark per $1M | B5: =B3/B4 -> 3280.3273
A7: In units of value | B7: Kenya | C7: Malawi | D7: Mozambique | E7: Rwanda | F7: Uganda
A8: Donation Size | B8: =1*10^6 -> 1000000 | C8: =1*10^6 -> 1000000 | D8: =1*10^6 -> 1000000 | E8: =1*10^6 -> 1000000 | F8: =1*10^6 -> 1000000
A9: Estimate of where marginal $ goes | B9: 0.16 | C9: 0.33 | D9: 0.02 | E9: 0.3 | F9: 0.18
A10: Consumption benefits to recipients | B10: 4196 | C10: 6746 | D10: 6095 | E10: 5736 | F10: 4517
A11: Spillover benefits to non-recipients | B11: 2833 | C11: 3985 | D11: 3600 | E11: 3630 | F11: 2859
A12: Mortality benefits | B12: 1042 | C12: 1106 | D12: 1701 | E12: 837 | F12: 1162
A13: Pre-Adjustment Value Units | B13: =SUM(B10:B12) -> 8071 | C13: =SUM(C10:C12) -> 11837 | D13: =SUM(D10:D12) -> 11396 | E13: =SUM(E10:E12) -> 10203 | F13: =SUM(F10:F12) -> 8538
A14: Additional benefits and downsides | B14: 646 | C14: 947 | D14: 912 | E14: 816 | F14: 683
A15: Total Units Value | B15: =SUM(B13:B14) -> 8717 | C15: =SUM(C13:C14) -> 12784 | D15: =SUM(D13:D14) -> 12308 | E15: =SUM(E13:E14) -> 11019 | F15: =SUM(F13:F14) -> 9221
A17: Adjustment factors (From GW CEA)
A18: Reduced morbidity adjustment | B18: 0.1 | C18: 0.1 | D18: 0.1 | E18: 0.1 | F18: 0.1
A19: Developmental effects | B19: 0.05 | C19: 0.05 | D19: 0.05 | E19: 0.05 | F19: 0.05
A20: Leverage & funging | B20: 0.02 | C20: 0.02 | D20: 0.02 | E20: 0.02 | F20: 0.02
A21: Risk of wastage/fraud | B21: -0.02 | C21: -0.02 | D21: -0.02 | E21: -0.02 | F21: -0.02
A22: Within-org fungibility | B22: -0.05 | C22: -0.05 | D22: -0.05 | E22: -0.05 | F22: -0.05
A23: Psychological spillovers | B23: -0.02 | C23: -0.02 | D23: -0.02 | E23: -0.02 | F23: -0.02
A24: Non-morbidity adjustment effects | B24: =1+SUM(B19:B23) -> 0.98 | C24: =1+SUM(C19:C23) -> 0.98 | D24: =1+SUM(D19:D23) -> 0.98 | E24: =1+SUM(E19:E23) -> 0.98 | F24: =1+SUM(F19:F23) -> 0.98
A26: Morbidity benefits as percent pre-adjustment value | B26: =B18*B24 -> 0.098 | C26: =C18*C24 -> 0.098 | D26: =D18*D24 -> 0.098 | E26: =E18*E24 -> 0.098 | F26: =F18*F24 -> 0.098
A28: Adj. Consumption benefits (all) | B28: =(B10+B11)*B24 -> 6888.42 | C28: =(C10+C11)*C24 -> 10516.38 | D28: =(D10+D11)*D24 -> 9501.1 | E28: =(E10+E11)*E24 -> 9178.68 | F28: =(F10+F11)*F24 -> 7228.48
A29: Adj. Mortality benefits | B29: =B12*B24 -> 1021.16 | C29: =C12*C24 -> 1083.88 | D29: =D12*D24 -> 1666.98 | E29: =E12*E24 -> 820.26 | F29: =F12*F24 -> 1138.76
A30: Adj. Morbidity effects | B30: =B26*B13 -> 790.958 | C30: =C26*C13 -> 1160.026 | D30: =D26*D13 -> 1116.808 | E30: =E26*E13 -> 999.894 | F30: =F26*F13 -> 836.724
A31: Total value units | B31: =SUM(B28:B30) -> 8700.538 | C31: =SUM(C28:C30) -> 12760.286 | D31: =SUM(D28:D30) -> 12284.888 | E31: =SUM(E28:E30) -> 10998.834 | F31: =SUM(F28:F30) -> 9203.964
H32: Slightly off, most likely due to the way morbidity effects were added.
A33: Weighted average units value per $1M | B33: Units value/$1M | C33: 1/Moral weight of benefit | D33: Units outcome | E33: Unit | F33: Percent value | H33: Reciprocal of GW's moral weights for each benefit stream
A34: Consumption benefits | B34: =SUMPRODUCT(B$9:F$9, B28:F28) -> 8817.305 | C34: 1 | D34: =B34*C34 -> 8817.305 | E34: consumption doublings / $1M | F34: =B34/$B$37 -> 0.81603617
A35: Mortality benefits | B35: =SUMPRODUCT(B$9:F$9, B29:F29) -> 1005.4604 | C35: =1/116 -> 0.0086206897 | D35: =B35*C35 -> 8.6677621 | E35: lives saved / $M | F35: =B35/$B$37 -> 0.093054743
A36: Morbidity benefits | B36: =SUMPRODUCT(B$9:F$9, B30:F30) -> 982.27654 | C36: =1/2.3 -> 0.43478261 | D36: =B36*C36 -> 427.07676 | E36: YLDs averted/$1M | F36: =B36/$B$37 -> 0.090909091
A37: Total value units | B37: =SUMPRODUCT(B$9:F$9, B31:F31) -> 10805.042
